<?xml version='1.0' ?>
<robot name="Two_wheeledBot">
    <link name="base_link">
        <inertial>
            <origin xyz="-7.592662129010022e-07 -0.0006085434678869461 0.019993521445171088" rpy="0.0 0.0 0.0" />
            <mass value="1.2850428455001508" />
            <inertia ixx="0.0044823768091858136" iyy="0.0025684388956093165" izz="0.0066955321803657715" ixy="-7.905662076458395e-08" iyz="-1.48956853669767e-06" ixz="-1.0244110488820415e-07" />
        </inertial>
        <visual name="base_link_visual">
            <origin xyz="0.0 0.0 0.0" rpy="0.0 0.0 0.0" />
            <geometry>
                <mesh filename="/home/ros2_ws/src/lab7/meshes/base_link.stl" scale="0.001 0.001 0.001" />
            </geometry>
            <material name="black">
                <color rgba="0 0 0 1"/>
            </material>
        </visual>
        <collision name="base_link_collision">
            <origin xyz="0.0 0.0 0.0" rpy="0.0 0.0 0.0" />
            <geometry>
                <mesh filename="/home/ros2_ws/src/lab7/meshes/base_link.stl" scale="0.001 0.001 0.001" />
            </geometry>
        </collision>
    </link>

    <link name="left_wheel">
        <inertial>
            <origin xyz="-3.552713678800501e-17 0.0 0.00999999999999984" rpy="0.0 -0.0 0.0" />
            <mass value="0.09349379737083224" />
            <inertia ixx="4.051397886069199e-05" iyy="4.051397886069481e-05" izz="7.479503789666238e-05" ixy="0.0" iyz="-5.421010862427522e-20" ixz="2.710505431213761e-20" />
        </inertial>
        <visual name="left_wheel_visual">
            <origin xyz="-0.02 0.08 -0.08" rpy="-3.141592653589793 -1.5707963267948966 0" />
            <geometry>
                <mesh filename="/home/ros2_ws/src/lab7/meshes/left_wheel.stl" scale="0.001 0.001 0.001" />
            </geometry>
            <material name="blue">
                <color rgba="0 0 1 1"/>
            </material>
        </visual>
        <collision name="left_wheel_collision">
            <origin xyz="-0.02 0.08 -0.08" rpy="-3.141592653589793 -1.5707963267948966 0" />
            <geometry>
                <mesh filename="/home/ros2_ws/src/lab7/meshes/left_wheel.stl" scale="0.001 0.001 0.001" />
            </geometry>
        </collision>
    </link>

    <link name="right_wheel">
        <inertial>
            <origin xyz="-5.639932965095795e-16 -1.0791367799356522e-15 0.009999999999999823" rpy="0.0 -0.0 0.0" />
            <mass value="0.09349379737083224" />
            <inertia ixx="4.051397886067388e-05" iyy="4.051397886068093e-05" izz="7.479503789667587e-05" ixy="1.1926223897340549e-18" iyz="1.0842021724855044e-19" ixz="-2.710505431213761e-20" />
        </inertial>
        <visual name="right_wheel_visual">
            <origin xyz="0.03950147074894218 -0.07238531486890443 -0.07999999999999999" rpy="-0.7445231003245201 1.5707963267948966 0" />
            <geometry>
                <mesh filename="/home/ros2_ws/src/lab7/meshes/right_wheel.stl" scale="0.001 0.001 0.001" />
            </geometry>
            <material name="green">
                <color rgba="0 1 0 1"/>
            </material>
        </visual>
        <collision name="right_wheel_collision">
            <origin xyz="0.03950147074894218 -0.07238531486890443 -0.07999999999999999" rpy="-0.7445231003245201 1.5707963267948966 0" />
            <geometry>
                <mesh filename="/home/ros2_ws/src/lab7/meshes/right_wheel.stl" scale="0.001 0.001 0.001" />
            </geometry>
        </collision>
    </link>

    <link name="lidar">
        <inertial>
            <origin xyz="4.131345610093595e-09 4.070935446520707e-09 0.014999999999999894" rpy="0.0 -0.0 0.0" />
            <mass value="0.03996105855366216" />
            <inertia ixx="6.993185246890153e-06" iyy="6.993185246891427e-06" izz="7.992211710731263e-06" ixy="7.411538288475128e-21" iyz="5.421010862427522e-20" ixz="-1.1858461261560205e-20" />
        </inertial>
        <visual name="lidar_visual">
            <origin xyz="-0.00021974 0.06680222000000001 -0.045" rpy="0.0 -0.0 0.0" />
            <geometry>
                <mesh filename="/home/ros2_ws/src/lab7/meshes/lidar.stl" scale="0.001 0.001 0.001" />
            </geometry>
            <material name="red">
                <color rgba="1 0 0 1"/>
            </material>
        </visual>
        <collision name="lidar_collision">
            <origin xyz="-0.00021974 0.06680222000000001 -0.045" rpy="0.0 -0.0 0.0" />
            <geometry>
                <mesh filename="/home/ros2_ws/src/lab7/meshes/lidar.stl" scale="0.001 0.001 0.001" />
            </geometry>
        </collision>
    </link>

    <joint name="base_link_Revolute-5" type="continuous">
        <origin xyz="-0.08000000000000014 0.08 0.020000000000000035" rpy="-0.0 -1.5707963267948966 0" />
        <parent link="base_link" />
        <child link="right_wheel" />
        <axis xyz="0.0 0.0 1.0" />
    </joint>

    <joint name="base_link_Revolute-6" type="continuous">
        <origin xyz="0.08000000000000014 0.08 0.020000000000000035" rpy="-3.141592653589793 -1.5707963267948966 0" />
        <parent link="base_link" />
        <child link="left_wheel" />
        <axis xyz="0.0 0.0 1.0" />
    </joint>

    <joint name="base_link_Rigid-7" type="fixed">
        <origin xyz="0.00021974000000000039 -0.06680222000000001 0.04500000000000008" rpy="0.0 -0.0 0.0" />
        <parent link="base_link" />
        <child link="lidar" />
    </joint>

    <gazebo reference="base_link">
        <material>Gazebo/Black</material>
    </gazebo>

    <gazebo reference="left_wheel">
        <material>Gazebo/Blue</material>
    </gazebo>

    <gazebo reference="right_wheel">
        <material>Gazebo/Green</material>
    </gazebo>

    <gazebo reference="lidar">
        <material>Gazebo/Red</material>
    </gazebo>

    <gazebo>
        <plugin filename="libgazebo_ros_diff_drive.so" name="differential_drive_controller">
            <left_joint>base_link_Revolute-6</left_joint>
            <right_joint>base_link_Revolute-5</right_joint>
            <wheel_separation>0.16</wheel_separation>
            <wheel_diameter>0.04</wheel_diameter>
            <max_wheel_torque>20</max_wheel_torque>
            <max_wheel_acceleration>1.0</max_wheel_acceleration>
            <robotNamespace>/</robotNamespace>
            <publish_odom>true</publish_odom>
            <publish_odom_tf>true</publish_odom_tf>
            <publish_wheel_tf>true</publish_wheel_tf>
            <odometry_topic>odom</odometry_topic>
            <odometry_frame>odom</odometry_frame>
            <robot_base_frame>base_link</robot_base_frame>
        </plugin>
    </gazebo>
</robot>